<?xml version="1.0"?>
<robot name="6dof_robot">

  <link name="base_link">
    <visual>
      <geometry>
        <box size="4 4 1"/>
      </geometry>
    </visual>
    <collision>
      <geometry>
        <box size="4 4 1"/>
      </geometry>
    </collision>
  </link>

  <link name="rotator1">
    <visual>
      <geometry>
        <cylinder radius="2" length="1"/>
      </geometry>
    </visual>
    <collision>
      <geometry>
        <cylinder radius="2" length="1"/>
      </geometry>
    </collision>
  </link>

  <link name="pivot1">
    <visual>
      <origin xyz="0 0 0" rpy="0 1.57 0"/>
      <geometry>
        <cylinder radius="1" length="2"/>
      </geometry>
    </visual>
    <collision>
      <origin xyz="0 0 0" rpy="0 1.57 0"/>
      <geometry>
        <cylinder radius="1" length="2"/>
      </geometry>
    </collision>
  </link>

  <link name="arm1">
    <visual>
      <origin xyz="0 0 6" rpy="0 0 0"/>
      <geometry>
        <cylinder radius="1" length="10"/>
      </geometry>
    </visual>
    <collision>
      <origin xyz="0 0 6" rpy="0 0 0"/>
      <geometry>
        <cylinder radius="1" length="10"/>
      </geometry>
    </collision>
  </link>

  <link name="pivot2">
    <visual>
      <origin xyz="0 0 0" rpy="0 1.57 0"/>
      <geometry>
        <cylinder radius="1" length="2"/>
      </geometry>
    </visual>
    <collision>
      <origin xyz="0 0 0" rpy="0 1.57 0"/>
      <geometry>
        <cylinder radius="1" length="2"/>
      </geometry>
    </collision>
  </link>

  <link name="arm2">
    <visual>
      <origin xyz="0 0 4" rpy="0 0 0"/>
      <geometry>
        <cylinder radius="1" length="6"/>
      </geometry>
    </visual>
    <collision>
      <origin xyz="0 0 4" rpy="0 0 0"/>
      <geometry>
        <cylinder radius="1" length="6"/>
      </geometry>
    </collision>
  </link>

  <link name="pivot3">
    <visual>
      <origin xyz="0 0 0" rpy="0 1.57 0"/>
      <geometry>
        <cylinder radius="1" length="2"/>
      </geometry>
    </visual>
    <collision>
      <origin xyz="0 0 0" rpy="0 1.57 0"/>
      <geometry>
        <cylinder radius="1" length="2"/>
      </geometry>
    </collision>
  </link>

  <link name="arm3">
    <visual>
      <origin xyz="0 0 2.5" rpy="0 0 0"/>
      <geometry>
        <cylinder radius="1" length="3"/>
      </geometry>
    </visual>
    <collision>
      <origin xyz="0 0 2.5" rpy="0 0 0"/>
      <geometry>
        <cylinder radius="1" length="10"/>
      </geometry>
    </collision>
  </link>

  <link name="sphere_end">
    <visual>
      <origin xyz="0 0 0" rpy="0 0 0"/>
      <geometry>
        <sphere radius="1.0"/>
      </geometry>
      <material name="white">
        <color rgba="1 1 1 1"/> <!-- White -->
      </material>
    </visual>
    <collision>
      <geometry>
        <sphere radius="0"/>
      </geometry>
    </collision>
  </link>

  <link name="end_effector">
    <visual>
    <origin xyz="0 0 0" rpy="0 0 0"/>
      <geometry>
        <cylinder length="2.0" radius="0.2"/>
      </geometry>
      <material name="white">
        <color rgba="1 1 1 1"/> <!-- White -->
      </material>
    </visual>
    <collision>
      <geometry>
        <cylinder length="2.0" radius="0.2"/>
      </geometry>
    </collision>
  </link>

  <!-- Joints definition -->
  <joint name="base_to_rotator1" type="continuous">
    <parent link="base_link"/>
    <child link="rotator1"/>
    <origin xyz="0 0 1" rpy="0 0 0"/> 
    <axis xyz="0 0 1"/>
  </joint>

  <joint name="rotator1_to_pivot1" type="fixed">
    <parent link="rotator1"/>
    <child link="pivot1"/>
    <origin xyz="0 0 1.5" rpy="0 0 0"/> 
  </joint>

  <joint name="pivot1_to_arm1" type="revolute">
    <parent link="pivot1"/>
    <child link="arm1"/>
    <axis xyz="1 0 0"/>
    <limit effort="30" velocity="1.0" lower="-1.57" upper="1.57"/>
  </joint>

  <joint name="arm1_to_pivot2" type="continuous">
    <parent link="arm1"/>
    <child link="pivot2"/>
    <origin xyz="0 0 12" rpy="0 0 0"/> 
    <axis xyz="0 0 1"/>
  </joint>

  <joint name="pivot2_to_arm2" type="revolute">
    <parent link="pivot2"/>
    <child link="arm2"/>
    <axis xyz="1 0 0"/>
    <limit effort="30" velocity="1.0" lower="-1.57" upper="1.57"/>
  </joint>

  <joint name="arm2_to_pivot3" type="continuous">
    <parent link="arm2"/>
    <child link="pivot3"/>
    <origin xyz="0 0 8" rpy="0 0 0"/> 
    <axis xyz="0 0 1"/>
  </joint>

  <joint name="pivot3_to_arm3" type="continuous">
    <parent link="pivot3"/>
    <child link="arm3"/>
    <axis xyz="1 0 0"/>
    <limit effort="30" velocity="1.0" lower="-1.57" upper="1.57"/>
  </joint>


  <joint name="arm3_to_sphere_end" type="fixed">
    <parent link="arm3"/>
    <child link="sphere_end"/>
    <origin xyz="0 0 5.0" rpy="0 0 0"/> 
  </joint>

  <joint name="sphere_end_to_end_effector" type="fixed">
    <parent link="sphere_end"/>
    <child link="end_effector"/>
    <origin xyz="0 0 1.0" rpy="0 0 0"/> 
  </joint>

</robot>
